<?xml version="1.0" ?>
<!-- =================================================================================== -->
<!-- |    This document was autogenerated by xacro from hc10_with_env.xacro            | -->
<!-- |    EDITING THIS FILE BY HAND IS NOT RECOMMENDED                                 | -->
<!-- =================================================================================== -->
<robot name="yaskawa_4">
  <material name="silver">
    <color rgba="0.700 0.700 0.700 1.000"/>
  </material>
  <link name="table_link">
    <visual>
      <origin rpy="0 0 0" xyz="0 0 0"/>
      <geometry>
        <mesh filename="package://yaskawa4/meshes/env/table.stl" scale="0.01 0.01 0.01"/>
      </geometry>
      <material name="silver"/>
    </visual>
    <collision>
      <origin rpy="0 0 0" xyz="0 0 0"/>
      <geometry>
        <mesh filename="package://yaskawa4/meshes/env/table.stl" scale="0.01 0.01 0.01"/>
      </geometry>
    </collision>
  </link>
  <!-- <joint name="table_link-base" type="fixed">
      <parent link="table_link" />
      <child link="base_table" />
  </joint> -->
  <!-- Properties -->
  <material name="yaskawa_blue">
    <color rgba="0.12941 0.14902 0.74902 1"/>
  </material>
  <gazebo>
    <plugin filename="libgazebo_ros_control.so" name="gazebo_ros_control">
      <robotNamespace>/yaskawa_4</robotNamespace>
      <robotSimType>gazebo_ros_control/DefaultRobotHWSim</robotSimType>
    </plugin>
  </gazebo>
  <link name="walls_link">
    <inertial>
      <origin rpy="0 0 0" xyz="-0.04720668354347962 0.018066716841360707 0.07080670574116438"/>
      <mass value="17.370821533898557"/>
      <inertia ixx="0.142346" ixy="-0.012291" ixz="-0.015362" iyy="0.109318" iyz="-0.007628" izz="0.181525"/>
    </inertial>
    <visual>
      <origin rpy="0 0 0" xyz="0 0 0"/>
      <geometry>
        <mesh filename="package://yaskawa4/meshes/env/walls.stl" scale="0.01 0.01 0.01"/>
      </geometry>
      <material name="silver"/>
    </visual>
    <collision>
      <origin rpy="0 0 0" xyz="0 0 0"/>
      <geometry>
        <mesh filename="package://yaskawa4/meshes/env/walls.stl" scale="0.01 0.01 0.01"/>
      </geometry>
    </collision>
  </link>
  <link name="end_effector_link">
    <visual>
      <geometry>
        <mesh filename="package://yaskawa4/meshes/env/GEH6040IL-03-B(01).stl" scale="0.001 0.001 0.001"/>
      </geometry>
      <material name="silver"/>
    </visual>
    <collision>
      <geometry>
        <mesh filename="package://yaskawa4/meshes/env/GEH6040IL-03-B(01).stl" scale="0.001 0.001 0.001"/>
      </geometry>
    </collision>
  </link>
  <link name="yaska4_base_link">
    <visual>
      <geometry>
        <mesh filename="package://motoman_hc10_support/meshes/hc10/visual/base_link.dae"/>
      </geometry>
      <material name="yaskawa_blue"/>
    </visual>
    <collision>
      <geometry>
        <mesh filename="package://motoman_hc10_support/meshes/hc10/collision/base_link.stl"/>
      </geometry>
    </collision>
    <inertial>
      <mass value="0.1"/>
      <inertia ixx="0.03" ixy="0.0" ixz="0.0" iyy="0.03" iyz="0.0" izz="0.03"/>
    </inertial>
  </link>
  <link name="yaska4_link_1_s">
    <visual>
      <geometry>
        <mesh filename="package://motoman_hc10_support/meshes/hc10/visual/link_1_s.dae"/>
      </geometry>
      <material name="yaskawa_blue"/>
    </visual>
    <collision>
      <geometry>
        <mesh filename="package://motoman_hc10_support/meshes/hc10/collision/link_1_s.stl"/>
      </geometry>
    </collision>
    <inertial>
      <mass value="0.1"/>
      <inertia ixx="0.03" ixy="0.0" ixz="0.0" iyy="0.03" iyz="0.0" izz="0.03"/>
    </inertial>
  </link>
  <link name="yaska4_link_2_l">
    <visual>
      <geometry>
        <mesh filename="package://motoman_hc10_support/meshes/hc10/visual/link_2_l.dae"/>
      </geometry>
      <material name="yaskawa_blue"/>
    </visual>
    <collision>
      <geometry>
        <mesh filename="package://motoman_hc10_support/meshes/hc10/collision/link_2_l.stl"/>
      </geometry>
    </collision>
    <inertial>
      <mass value="0.1"/>
      <inertia ixx="0.03" ixy="0.0" ixz="0.0" iyy="0.03" iyz="0.0" izz="0.03"/>
    </inertial>
  </link>
  <link name="yaska4_link_3_u">
    <visual>
      <geometry>
        <mesh filename="package://motoman_hc10_support/meshes/hc10/visual/link_3_u.dae"/>
      </geometry>
      <material name="yaskawa_blue"/>
    </visual>
    <collision>
      <geometry>
        <mesh filename="package://motoman_hc10_support/meshes/hc10/collision/link_3_u.stl"/>
      </geometry>
    </collision>
    <inertial>
      <mass value="0.1"/>
      <inertia ixx="0.03" ixy="0.0" ixz="0.0" iyy="0.03" iyz="0.0" izz="0.03"/>
    </inertial>
  </link>
  <link name="yaska4_link_4_r">
    <visual>
      <geometry>
        <mesh filename="package://motoman_hc10_support/meshes/hc10/visual/link_4_r.dae"/>
      </geometry>
      <material name="yaskawa_blue"/>
    </visual>
    <collision>
      <geometry>
        <mesh filename="package://motoman_hc10_support/meshes/hc10/collision/link_4_r.stl"/>
      </geometry>
    </collision>
    <inertial>
      <mass value="0.1"/>
      <inertia ixx="0.03" ixy="0.0" ixz="0.0" iyy="0.03" iyz="0.0" izz="0.03"/>
    </inertial>
  </link>
  <link name="yaska4_link_5_b">
    <visual>
      <geometry>
        <mesh filename="package://motoman_hc10_support/meshes/hc10/visual/link_5_b.dae"/>
      </geometry>
      <material name="yaskawa_blue"/>
    </visual>
    <collision>
      <geometry>
        <mesh filename="package://motoman_hc10_support/meshes/hc10/collision/link_5_b.stl"/>
      </geometry>
    </collision>
    <inertial>
      <mass value="0.1"/>
      <inertia ixx="0.03" ixy="0.0" ixz="0.0" iyy="0.03" iyz="0.0" izz="0.03"/>
    </inertial>
  </link>
  <link name="yaska4_link_6_t">
    <visual>
      <geometry>
        <mesh filename="package://motoman_hc10_support/meshes/hc10/visual/link_6_t.dae"/>
      </geometry>
      <material name="yaskawa_blue"/>
    </visual>
    <collision>
      <geometry>
        <mesh filename="package://motoman_hc10_support/meshes/hc10/collision/link_6_t.stl"/>
      </geometry>
    </collision>
    <inertial>
      <mass value="0.1"/>
      <inertia ixx="0.03" ixy="0.0" ixz="0.0" iyy="0.03" iyz="0.0" izz="0.03"/>
    </inertial>
  </link>
  <link name="yaska4_tool0"/>
  <!-- end of link list -->
  <!-- joint list -->
  <joint name="yaska4_joint_1_s" type="revolute">
    <parent link="yaska4_base_link"/>
    <child link="yaska4_link_1_s"/>
    <origin rpy="0 0 0" xyz="0 0 0.275"/>
    <axis xyz="0 0 1"/>
    <limit effort="368.48" lower="-3.14159265359" upper="3.14159265359" velocity="2.26892802759"/>
  </joint>
  <joint name="yaska4_joint_2_l" type="revolute">
    <parent link="yaska4_link_1_s"/>
    <child link="yaska4_link_2_l"/>
    <origin rpy="0 0 0" xyz="0 0 0"/>
    <axis xyz="0 1 0"/>
    <limit effort="368.48" lower="-3.14159265359" upper="3.14159265359" velocity="2.26892802759"/>
  </joint>
  <joint name="yaska4_joint_3_u" type="revolute">
    <parent link="yaska4_link_2_l"/>
    <child link="yaska4_link_3_u"/>
    <origin rpy="0 0 0" xyz="0 0 0.700"/>
    <axis xyz="0 -1 0"/>
    <limit effort="141.12" lower="-0.0872664625997" upper="6.19591884458" velocity="3.14159265359"/>
  </joint>
  <joint name="yaska4_joint_4_r" type="revolute">
    <parent link="yaska4_link_3_u"/>
    <child link="yaska4_link_4_r"/>
    <origin rpy="0 0 0" xyz="0 0 -0.500"/>
    <axis xyz="0 0 1"/>
    <limit effort="39.20" lower="-3.14159265359" upper="3.14159265359" velocity="3.14159265359"/>
  </joint>
  <joint name="yaska4_joint_5_b" type="revolute">
    <parent link="yaska4_link_4_r"/>
    <child link="yaska4_link_5_b"/>
    <origin rpy="0 0 0" xyz="0 0.162 0"/>
    <axis xyz="0 -1 0"/>
    <limit effort="31.36" lower="-3.14159265359" upper="3.14159265359" velocity="4.36332312999"/>
  </joint>
  <joint name="yaska4_joint_6_t" type="revolute">
    <parent link="yaska4_link_5_b"/>
    <child link="yaska4_link_6_t"/>
    <origin rpy="0 0 0" xyz="0 0 0"/>
    <axis xyz="0 0 1"/>
    <limit effort="31.36" lower="-3.14159265359" upper="3.14159265359" velocity="4.36332312999"/>
  </joint>
  <joint name="yaska4_joint_6_t-tool0" type="fixed">
    <origin rpy="3.14159265359 0 0" xyz="0 0 -0.130"/>
    <parent link="yaska4_link_6_t"/>
    <child link="yaska4_tool0"/>
  </joint>
  <!-- end of joint list -->
  <transmission name="trans_joint_1_s">
    <type>transmission_interface/SimpleTransmission</type>
    <joint name="yaska4_joint_1_s">
      <hardwareInterface>hardware_interface/EffortJointInterface</hardwareInterface>
    </joint>
    <actuator name="joint_1_s_motor">
      <hardwareInterface>hardware_interface/EffortJointInterface</hardwareInterface>
      <mechanicalReduction>1</mechanicalReduction>
    </actuator>
  </transmission>
  <transmission name="trans_joint_2_l">
    <type>transmission_interface/SimpleTransmission</type>
    <joint name="yaska4_joint_2_l">
      <hardwareInterface>hardware_interface/EffortJointInterface</hardwareInterface>
    </joint>
    <actuator name="joint_2_l_motor">
      <hardwareInterface>hardware_interface/EffortJointInterface</hardwareInterface>
      <mechanicalReduction>1</mechanicalReduction>
    </actuator>
  </transmission>
  <transmission name="trans_joint_3_u">
    <type>transmission_interface/SimpleTransmission</type>
    <joint name="yaska4_joint_3_u">
      <hardwareInterface>hardware_interface/EffortJointInterface</hardwareInterface>
    </joint>
    <actuator name="joint_3_u_motor">
      <hardwareInterface>hardware_interface/EffortJointInterface</hardwareInterface>
      <mechanicalReduction>1</mechanicalReduction>
    </actuator>
  </transmission>
  <transmission name="trans_joint_4_r">
    <type>transmission_interface/SimpleTransmission</type>
    <joint name="yaska4_joint_4_r">
      <hardwareInterface>hardware_interface/EffortJointInterface</hardwareInterface>
    </joint>
    <actuator name="joint_4_r_motor">
      <hardwareInterface>hardware_interface/EffortJointInterface</hardwareInterface>
      <mechanicalReduction>1</mechanicalReduction>
    </actuator>
  </transmission>
  <transmission name="trans_joint_5_b">
    <type>transmission_interface/SimpleTransmission</type>
    <joint name="yaska4_joint_5_b">
      <hardwareInterface>hardware_interface/EffortJointInterface</hardwareInterface>
    </joint>
    <actuator name="joint_5_b_motor">
      <hardwareInterface>hardware_interface/EffortJointInterface</hardwareInterface>
      <mechanicalReduction>1</mechanicalReduction>
    </actuator>
  </transmission>
  <transmission name="trans_joint_6_t">
    <type>transmission_interface/SimpleTransmission</type>
    <joint name="yaska4_joint_6_t">
      <hardwareInterface>hardware_interface/EffortJointInterface</hardwareInterface>
    </joint>
    <actuator name="joint_6_t_motor">
      <hardwareInterface>hardware_interface/EffortJointInterface</hardwareInterface>
      <mechanicalReduction>1</mechanicalReduction>
    </actuator>
  </transmission>
  <!-- linking every robots to world and workspaces -->
  <link name="world"/>
  <joint name="world_walls_joint" type="fixed">
    <parent link="world"/>
    <child link="walls_link"/>
  </joint>
  <joint name="world_table_joint" type="fixed">
    <parent link="world"/>
    <child link="table_link"/>
  </joint>
  <joint name="link_base" type="fixed">
    <origin rpy="0 0 0" xyz="0 0 0.6376"/>
    <parent link="table_link"/>
    <child link="yaska4_base_link"/>
  </joint>
  <joint name="end_effector" type="fixed">
    <parent link="yaska4_tool0"/>
    <child link="end_effector_link"/>
  </joint>
</robot>
